Workbook

Sheet Planilha1
B3: CIA | C3: 46023 | D3: 46054 | E3: 46082 | F3: 46113 | G3: 46143 | H3: 46174 | I3: 46204 | J3: 46235 | K3: 46266 | L3: 46296 | M3: 46327 | N3: 46357
B4: ENEL CE | C4: 5718986.1 | D4: 5066120 | E4: 6530518.4 | F4: 6064742.4 | G4: 6141379.6 | H4: 6767464.3 | I4: 6625456.5 | J4: 6136685.4 | K4: 6223152.6 | L4: 6316297.2 | M4: 5749554.6 | N4: 6872642.7
B5: ENEL RJ | C5: 3904584.9 | D5: 3458846.6 | E5: 4458651.1 | F5: 4140646.8 | G5: 4192970.2 | H5: 4620423.7 | I5: 4523469.2 | J5: 4189765.3 | K5: 4248800 | L5: 4312393.6 | M5: 3925455.3 | N5: 4692233.3
B6: ENEL SP | C6: 14794255 | D6: 13105378 | E6: 16893581 | F6: 15688681 | G6: 15886931 | H6: 17506529 | I6: 17139174 | J6: 15874788 | K6: 16098467 | L6: 16339420 | M6: 14873332 | N6: 17778611
B7: CPFL PAULISTA | C7: 17585340 | D7: 15657310 | E7: 20138018 | F7: 18729840 | G7: 18974745 | H7: 20911938 | I7: 16758560 | J7: 22120285 | K7: 22586868 | L7: 23041051 | M7: 21284464 | N7: 24914201
B8: RGE | C8: 10561150 | D8: 9403241.6 | E8: 12094201 | F8: 11248497 | G8: 11395579 | H8: 12558990 | I8: 10064614 | J8: 13284682 | K8: 13564895 | L8: 13837662 | M8: 12782716 | N8: 14962612
B9: CPFL SANTA CRUZ | C9: 1874994.7 | D9: 1669423.2 | E9: 2147167.9 | F9: 1997024.3 | G9: 2023136.7 | H9: 2229685.3 | I9: 1786841.3 | J9: 2358522.4 | K9: 2408270.6 | L9: 2456696.9 | M9: 2269405 | N9: 2656417
B10: CPFL PIRATININGA | C10: 6435699 | D10: 5730098.8 | E10: 7369901.4 | F10: 6854551 | G10: 6944179 | H10: 7653132.6 | I10: 6133122.7 | J10: 8095350.9 | K10: 8266105.8 | L10: 8432323.1 | M10: 7789465.7 | N10: 9117839
B11: CELPE | C11: 11809117 | D11: 10110120 | E11: 11881801 | F11: 10987996 | G11: 11220647 | H11: 11535283 | I11: 12417878 | J11: 11501790 | K11: 11663852 | L11: 11838430 | M11: 10776203 | N11: 12881171
B12: COELBA | C12: 14469598 | D12: 12387833 | E12: 14558656 | F12: 13463486 | G12: 13748551 | H12: 14134071 | I12: 15215506 | J12: 14093033 | K12: 14291607 | L12: 14505515 | M12: 13203978 | N12: 15783175
B13: COSERN | C13: 4369820.6 | D13: 3741127.3 | E13: 4396716.3 | F13: 4065974.9 | G13: 4152064.4 | H13: 4268491.6 | I13: 4595085.2 | J13: 4256098 | K13: 4316067.3 | L13: 4380667.7 | M13: 3987603.4 | N13: 4766521.1
B14: ELEKTRO | C14: 6445750.4 | D14: 5518389.6 | E14: 6485423.2 | F14: 5997559.6 | G14: 6124546.8 | H14: 6296284 | I14: 6778029.3 | J14: 6278002.7 | K14: 6366461 | L14: 6461750.6 | M14: 5881956.9 | N14: 7030907.7
B15: COPEL | C15: 0 | D15: 0 | E15: 0 | F15: 0 | G15: 0 | H15: 0 | I15: 4496537 | J15: 4681123.7 | K15: 5535766.4 | L15: 5089729.1 | M15: 5135519.2 | N15: 5283364.5
B16: Total | C16: =SUM(C4:C15) -> 97969295 | D16: =SUM(D4:D15) -> 85847887 | E16: =SUM(E4:E15) -> 1.0695464e+08 | F16: =SUM(F4:F15) -> 99238999 | G16: =SUM(G4:G15) -> 1.0080473e+08 | H16: =SUM(H4:H15) -> 1.0848229e+08 | I16: =SUM(I4:I15) -> 1.0653427e+08 | J16: =SUM(J4:J15) -> 1.1287013e+08 | ... N16: =SUM(N4:N15) -> 1.267397e+08
B20: Canal | C20: 46023 | D20: 46054 | E20: 46082 | F20: 46113 | G20: 46143 | H20: 46174 | I20: 46204 | J20: 46235 | K20: 46266 | L20: 46296 | M20: 46327 | N20: 46357
B21: Reallizi | C21: 22840658 | D21: 18448709 | E21: 22800839 | F21: 21003964 | G21: 21313600 | H21: 22529366 | I21: 26633568 | J21: 28217532 | K21: 28892578 | L21: 29252984 | M21: 26914914 | N21: 31684924
B22: Corban | C22: 38784705 | D22: 35575910 | E22: 44581943 | F22: 41530329 | G22: 42366951 | H22: 45557683 | I22: 43125037 | J22: 45689789 | K22: 46782823 | L22: 47366392 | M22: 43580591 | N22: 51304185
B23: Lojas | C23: 19957206 | D23: 17539226 | E23: 21826466 | F23: 20267936 | G23: 20408184 | H23: 22545765 | I23: 20544234 | J23: 21766050 | K23: 22286758 | L23: 22564763 | M23: 20761254 | N23: 24440679
B24: Canal Interno | C24: 14381246 | D24: 12500898 | E24: 15488790 | F24: 14311332 | G24: 14518114 | H24: 15462722 | I24: 13849720 | J24: 14673396 | K24: 15024427 | L24: 15211842 | M24: 13996022 | N24: 16476475
B25: Canal Digital | C25: 2005480.6 | D25: 1783144.4 | E25: 2256598 | F25: 2125438 | G25: 2197880.9 | H25: 2386756.3 | I25: 2381714.1 | J25: 2523360.5 | K25: 2583726.7 | L25: 2615956.1 | M25: 2406873.5 | N25: 2833432.9
B26: Total | C26: =SUM(C21:C25) -> 97969296 | D26: =SUM(D21:D25) -> 85847887 | E26: =SUM(E21:E25) -> 1.0695464e+08 | F26: =SUM(F21:F25) -> 99238999 | G26: =SUM(G21:G25) -> 1.0080473e+08 | H26: =SUM(H21:H25) -> 1.0848229e+08 | I26: =SUM(I21:I25) -> 1.0653427e+08 | J26: =SUM(J21:J25) -> 1.1287013e+08 | ... N26: =SUM(N21:N25) -> 1.267397e+08

Sheet Base Rateio
A1: Mês | B1: Canal | C1: Cia | D1: Produção
A2: jan/26 | B2: =Planilha1!B21 -> Reallizi | C2: =Planilha1!B4 -> ENEL CE | D2: 1333330
A3: jan/26 | B3: =Planilha1!B21 -> Reallizi | C3: =Planilha1!B5 -> ENEL RJ | D3: 910318.77
A4: jan/26 | B4: =Planilha1!B21 -> Reallizi | C4: =Planilha1!B6 -> ENEL SP | D4: 3449147.3
A5: jan/26 | B5: =Planilha1!B21 -> Reallizi | C5: =Planilha1!B7 -> CPFL PAULISTA | D5: 4099863.5
A6: jan/26 | B6: =Planilha1!B21 -> Reallizi | C6: =Planilha1!B8 -> RGE | D6: 2462236.9
A7: jan/26 | B7: =Planilha1!B21 -> Reallizi | C7: =Planilha1!B9 -> CPFL SANTA CRUZ | D7: 437138.12
A8: jan/26 | B8: =Planilha1!B21 -> Reallizi | C8: =Planilha1!B10 -> CPFL PIRATININGA | D8: 1500425.2
A9: jan/26 | B9: =Planilha1!B21 -> Reallizi | C9: =Planilha1!B11 -> CELPE | D9: 2753189.1
A10: jan/26 | B10: =Planilha1!B21 -> Reallizi | C10: =Planilha1!B12 -> COELBA | D10: 3373456.2
A11: jan/26 | B11: =Planilha1!B21 -> Reallizi | C11: =Planilha1!B13 -> COSERN | D11: 1018784.3
A12: jan/26 | B12: =Planilha1!B21 -> Reallizi | C12: =Planilha1!B14 -> ELEKTRO | D12: 1502768.6
A13: jan/26 | B13: =Planilha1!B21 -> Reallizi | C13: =Planilha1!B15 -> COPEL | D13: 0
A14: jan/26 | B14: =Planilha1!B22 -> Corban | C14: =Planilha1!B4 -> ENEL CE | D14: 2264068.4
A15: jan/26 | B15: =Planilha1!B22 -> Corban | C15: =Planilha1!B5 -> ENEL RJ | D15: 1545771.8
A16: jan/26 | B16: =Planilha1!B22 -> Corban | C16: =Planilha1!B6 -> ENEL SP | D16: 5856843.5
A17: jan/26 | B17: =Planilha1!B22 -> Corban | C17: =Planilha1!B7 -> CPFL PAULISTA | D17: 6961795.8
A18: jan/26 | B18: =Planilha1!B22 -> Corban | C18: =Planilha1!B8 -> RGE | D18: 4181015
A19: jan/26 | B19: =Planilha1!B22 -> Corban | C19: =Planilha1!B9 -> CPFL SANTA CRUZ | D19: 742284.79
A20: jan/26 | B20: =Planilha1!B22 -> Corban | C20: =Planilha1!B10 -> CPFL PIRATININGA | D20: 2547805.3
A21: jan/26 | B21: =Planilha1!B22 -> Corban | C21: =Planilha1!B11 -> CELPE | D21: 4675067.9
A22: jan/26 | B22: =Planilha1!B22 -> Corban | C22: =Planilha1!B12 -> COELBA | D22: 5728315.9
A23: jan/26 | B23: =Planilha1!B22 -> Corban | C23: =Planilha1!B13 -> COSERN | D23: 1729952.2
A24: jan/26 | B24: =Planilha1!B22 -> Corban | C24: =Planilha1!B14 -> ELEKTRO | D24: 2551784.5
A25: jan/26 | B25: =Planilha1!B22 -> Corban | C25: =Planilha1!B15 -> COPEL | D25: 0
A26: jan/26 | B26: =Planilha1!B23 -> Lojas | C26: =Planilha1!B4 -> ENEL CE | D26: 1165007.7
A27: jan/26 | B27: =Planilha1!B23 -> Lojas | C27: =Planilha1!B5 -> ENEL RJ | D27: 795398.26
A28: jan/26 | B28: =Planilha1!B23 -> Lojas | C28: =Planilha1!B6 -> ENEL SP | D28: 3013719.8
A29: jan/26 | B29: =Planilha1!B23 -> Lojas | C29: =Planilha1!B7 -> CPFL PAULISTA | D29: 3582288.3
A30: jan/26 | B30: =Planilha1!B23 -> Lojas | C30: =Planilha1!B8 -> RGE | D30: 2151399.1
A31: jan/26 | B31: =Planilha1!B23 -> Lojas | C31: =Planilha1!B9 -> CPFL SANTA CRUZ | D31: 381952.9
A32: jan/26 | B32: =Planilha1!B23 -> Lojas | C32: =Planilha1!B10 -> CPFL PIRATININGA | D32: 1311008.4
A33: jan/26 | B33: =Planilha1!B23 -> Lojas | C33: =Planilha1!B11 -> CELPE | D33: 2405620.8
A34: jan/26 | B34: =Planilha1!B23 -> Lojas | C34: =Planilha1!B12 -> COELBA | D34: 2947584.2
A35: jan/26 | B35: =Planilha1!B23 -> Lojas | C35: =Planilha1!B13 -> COSERN | D35: 890170.85
A36: jan/26 | B36: =Planilha1!B23 -> Lojas | C36: =Planilha1!B14 -> ELEKTRO | D36: 1313056
A37: jan/26 | B37: =Planilha1!B23 -> Lojas | C37: =Planilha1!B15 -> COPEL | D37: 0
A38: jan/26 | B38: =Planilha1!B24 -> Canal Interno | C38: =Planilha1!B4 -> ENEL CE | D38: 839509.39
A39: jan/26 | B39: =Planilha1!B24 -> Canal Interno | C39: =Planilha1!B5 -> ENEL RJ | D39: 573167.28
A40: jan/26 | B40: =Planilha1!B24 -> Canal Interno | C40: =Planilha1!B6 -> ENEL SP | D40: 2171699
...

Sheet Base Rateio Produto
A1: Mês | B1: Canal | C1: Produto | D1: Meta
A2: jan/26 | B2: CANAL DIGITAL | C2: Outros | D2: 45661.881
A3: jan/26 | B3: CANAL INTERNO | C3: Boleto | D3: 471426.43
A4: jan/26 | B4: CANAL INTERNO | C4: CP Auto | D4: 613214.8
A5: jan/26 | B5: CANAL INTERNO | C5: CP Refin | D5: 520969.42
A6: jan/26 | B6: CANAL INTERNO | C6: Crédito do Trabalhador | D6: 934345.72
A7: jan/26 | B7: CDC LOJISTA | C7: CDC Energia | D7: 7650000
A8: jan/26 | B8: CORBAN | C8: Boleto | D8: 765510
A9: jan/26 | B9: CORBAN | C9: CP Auto | D9: 1526292
A10: jan/26 | B10: CORBAN | C10: CP Refin | D10: 44205.441
A11: jan/26 | B11: CORBAN | C11: Crédito do Trabalhador | D11: 1252624.8
A12: jan/26 | B12: LOJAS | C12: Boleto | D12: 341683.53
A13: jan/26 | B13: LOJAS | C13: CP Auto | D13: 1482000
... A148: ago/26 | B148: REALLIZI | C148: Crédito do Trabalhador | D148: 318131.02
